Workbook

Sheet README
A1: 📄 README - Auto Service Center Analysis
A3: ═══════════════════════════════════════════════════════════════
A5: 🎯 Project Overview
A7: This project analyzes operational data from an auto service center
A8: to identify strengths, weaknesses, and opportunities for improvement.
A10: 📊 Dataset
A11: • Customers: 1,000 | Vehicles: 1,500 | Technicians: 30
A12: • Parts: 200 | Repair Orders: 10,000
A14: 🛠️ Skills Demonstrated
A15: • Data Analysis & Cleaning
A16: • Excel Dashboard Design
A17: • KPI Development & Tracking
... A52: 💻 GitHub: [Your GitHub]

Sheet Cover Page
A4: 📊 تقرير تحليل أداء مركز الصيانة
A7: إعداد: فريق تحليل البيانات
A9: التاريخ: يونيو 2026
A12: ═══════════════════════════════════════════
A14: 📋 محتويات التقرير
A16: 1️⃣ منهجية التحليل (Methodology)
A17: 2️⃣ لوحة التحكم والمؤشرات (Dashboard)
A18: 3️⃣ نقاط القوة والضعف (SWOT Analysis)
A19: 4️⃣ توصيات زيادة الربحية
A20: 5️⃣ الملخص التنفيذي (Executive Summary)
A22: ═══════════════════════════════════════════
A24: 📈 نظرة سريعة على البيانات
A26: البيان | B26: القيمة
A27: إجمالي أوامر الإصلاح | B27: 10000
A28: إجمالي العملاء | B28: 1000
A29: إجمالي المركبات | B29: 1500
A30: عدد الفنيين | B30: 30
A31: إجمالي قطع الغيار | B31: 200
A33: ═══════════════════════════════════════════
A35: ⚠️ ملاحظة: هذا التقرير تم إعداده بناءً على البيانات المتاحة
A36: والتي لا تتضمن معلومات زمنية (تواريخ)

Sheet Methodology
A1: 📐 منهجية التحليل (Methodology)
A3: 1️⃣ مصادر البيانات
A5: الجدول | B5: الوصف
A6: Dim_Customers | B6: بيانات العملاء (1,000 عميل)
A7: Dim_Vehicles | B7: بيانات المركبات (1,500 مركبة)
A8: Dim_Technicians | B8: بيانات الفنيين (30 فني)
A9: Dim_Parts | B9: قطع الغيار (200 قطعة)
A10: Fact_RepairOrders | B10: أوامر الإصلاح (10,000 أمر)
A12: 2️⃣ المؤشرات المحسوبة (KPIs)
A14: المؤشر | B14: الصيغة | C14: الهدف
A15: إجمالي الإيرادات | B15: SUM(Revenue) | C15: قياس حجم الأعمال
A16: هامش الربح | B16: (Revenue - Labor - Parts) / Revenue | C16: قياس الربحية
A17: متوسط CSI | B17: AVERAGE(CSI_Score) | C17: قياس رضا العملاء
A18: إنتاجية الفني | B18: عدد الأوامر / عدد الفنيين | C18: قياس الكفاءة
A19: تكلفة القطع % | B19: Parts_Cost / Revenue | C19: تحليل التكاليف
A21: 3️⃣ طرق التحليل المستخدمة
A23: التحليل | B23: الوصف
A24: التحليل الوصفي | B24: حساب الإحصائيات الأساسية (المجموع، المتوسط، العدد)
A25: تحليل التوزيع | B25: توزيع العملاء حسب المدينة والنوع
A26: تحليل الأداء | B26: مقارنة أداء الفنيين بناءً على CSI
A27: تحليل التكاليف | B27: تحليل هيكل التكاليف (عمالة، قطع غيار)
A28: تحليل SWOT | B28: تحديد نقاط القوة والضعف
A30: 4️⃣ معايير التقييم
A32: المعيار | B32: التصنيف
A33: CSI ≥ 85 | B33: ممتاز ✅
A34: CSI 70-84 | B34: جيد 🟡
A35: CSI < 70 | B35: يحتاج تحسين ⚠️
A36: هامش ربح > 15% | B36: صحي ✅
A38: 5️⃣ القيود والملاحظات
A40: ⚠️ البيانات لا تحتوي على تواريخ - لا يمكن التحليل الزمني
A41: ⚠️ أسماء العملاء عامة (Customer 1, 2, 3...)
A42: ⚠️ لا توجد بيانات عن نوع الخدمة المقدمة
A43: ⚠️ لا توجد بيانات مقارنة مع فترات سابقة

Sheet Dim_Customers
A1: Customer_ID | B1: Customer_Name | C1: City | D1: Customer_Type
A2: C0001 | B2: Customer 1 | C2: Giza | D2: Fleet
A3: C0002 | B3: Customer 2 | C3: Cairo | D3: Retail
A4: C0003 | B4: Customer 3 | C4: Alexandria | D4: Fleet
A5: C0004 | B5: Customer 4 | C5: Cairo | D5: Retail
A6: C0005 | B6: Customer 5 | C6: Alexandria | D6: Fleet
A7: C0006 | B7: Customer 6 | C7: Alexandria | D7: Fleet
A8: C0007 | B8: Customer 7 | C8: Giza | D8: Fleet
A9: C0008 | B9: Customer 8 | C9: Cairo | D9: Retail
A10: C0009 | B10: Customer 9 | C10: Alexandria | D10: Retail
A11: C0010 | B11: Customer 10 | C11: Cairo | D11: Retail
A12: C0011 | B12: Customer 11 | C12: Giza | D12: Fleet
... A1001: C1000 | B1001: Customer 1000 | C1001: Alexandria | D1001: Fleet

Sheet Dim_Vehicles
A1: Vehicle_ID | B1: Customer_ID | C1: Brand | D1: Model | E1: Model_Year
A2: V0001 | B2: C0608 | C2: Nissan | D2: Corolla | E2: 2025
A3: V0002 | B3: C0736 | C3: Kia | D3: Cerato | E3: 2016
A4: V0003 | B4: C0986 | C4: Nissan | D4: Elantra | E4: 2020
A5: V0004 | B5: C0887 | C5: Nissan | D5: Tucson | E5: 2018
A6: V0005 | B6: C0134 | C6: Nissan | D6: Elantra | E6: 2022
A7: V0006 | B7: C0659 | C7: Hyundai | D7: Corolla | E7: 2025
A8: V0007 | B8: C0357 | C8: Kia | D8: Corolla | E8: 2025
A9: V0008 | B9: C0332 | C9: Toyota | D9: Tucson | E9: 2022
A10: V0009 | B10: C0380 | C10: Kia | D10: Tucson | E10: 2023
A11: V0010 | B11: C0630 | C11: Nissan | D11: Cerato | E11: 2021
A12: V0011 | B12: C0469 | C12: Nissan | D12: Corolla | E12: 2023
A13: V0012 | B13: C0626 | C13: Kia | D13: Sunny | E13: 2024
... A1501: V1500 | B1501: C0415 | C1501: Hyundai | D1501: Sunny | E1501: 2022

Sheet Dim_Technicians
A1: Technician_ID | B1: Technician_Name | C1: Level
A2: T001 | B2: Tech 1 | C2: Master
A3: T002 | B3: Tech 2 | C3: Junior
A4: T003 | B4: Tech 3 | C4: Senior
A5: T004 | B5: Tech 4 | C5: Senior
A6: T005 | B6: Tech 5 | C6: Senior
A7: T006 | B7: Tech 6 | C7: Senior
A8: T007 | B8: Tech 7 | C8: Senior
A9: T008 | B9: Tech 8 | C9: Junior
A10: T009 | B10: Tech 9 | C10: Senior
A11: T010 | B11: Tech 10 | C11: Junior
A12: T011 | B12: Tech 11 | C12: Junior
... A31: T030 | B31: Tech 30 | C31: Master

Sheet Dim_Parts
A1: Part_ID | B1: Part_Name | C1: Category | D1: Unit_Cost
A2: P0001 | B2: Part 1 | C2: Electrical | D2: 349
A3: P0002 | B3: Part 2 | C3: Engine | D3: 2714
A4: P0003 | B4: Part 3 | C4: AC | D4: 645
A5: P0004 | B5: Part 4 | C5: AC | D5: 3791
A6: P0005 | B6: Part 5 | C6: Electrical | D6: 3344
A7: P0006 | B7: Part 6 | C7: Engine | D7: 1963
A8: P0007 | B8: Part 7 | C8: Electrical | D8: 2159
A9: P0008 | B9: Part 8 | C9: Brake | D9: 634
A10: P0009 | B10: Part 9 | C10: AC | D10: 2240
A11: P0010 | B11: Part 10 | C11: AC | D11: 1317
A12: P0011 | B12: Part 11 | C12: Engine | D12: 2251
A13: P0012 | B13: Part 12 | C13: Engine | D13: 3232
... A201: P0200 | B201: Part 200 | C201: Brake | D201: 1583

Sheet Fact_RepairOrders
A1: RO_Number | B1: Customer_ID | C1: Vehicle_ID | D1: Technician_ID | E1: Part_ID | F1: Mileage | G1: Labor_Hours | H1: Labor_Cost | I1: Parts_Cost | J1: Revenue | K1: CSI_Score
A2: RO000001 | B2: C0604 | C2: V1468 | D2: T017 | E2: P0189 | F2: 35791 | G2: 6.3 | H2: 2489.89 | I2: 3294 | J2: 6772.09 | K2: 69
A3: RO000002 | B3: C0918 | C3: V0490 | D3: T013 | E3: P0104 | F3: 247137 | G3: 7 | H3: 2339.49 | I3: 8395 | J3: 13252.99 | K3: 88
A4: RO000003 | B4: C0886 | C4: V1407 | D4: T009 | E4: P0143 | F4: 174813 | G4: 0.9 | H4: 2427.07 | I4: 6001 | J4: 10228.37 | K4: 68
A5: RO000004 | B5: C0918 | C5: V1038 | D5: T011 | E5: P0063 | F5: 199660 | G5: 5.4 | H5: 523.94 | I5: 734 | J5: 1478.14 | K5: 87
A6: RO000005 | B6: C0165 | C6: V0865 | D6: T013 | E6: P0029 | F6: 175479 | G6: 4.3 | H6: 1481.01 | I6: 8239 | J6: 12191.71 | K6: 90
A7: RO000006 | B7: C0303 | C7: V0570 | D7: T020 | E7: P0069 | F7: 194801 | G7: 5.5 | H7: 2928.3 | I7: 3531 | J7: 7518.6 | K7: 76
A8: RO000007 | B8: C0281 | C8: V0565 | D8: T023 | E8: P0149 | F8: 189871 | G8: 3.6 | H8: 2490.94 | I8: 2323 | J8: 5510.84 | K8: 98
A9: RO000008 | B9: C0557 | C9: V1235 | D9: T011 | E9: P0034 | F9: 82493 | G9: 1.7 | H9: 758.8 | I9: 8120 | J9: 11314.8 | K9: 97
A10: RO000009 | B10: C0247 | C10: V0046 | D10: T018 | E10: P0197 | F10: 117986 | G10: 5 | H10: 2949.18 | I10: 8907 | J10: 14528.28 | K10: 68
A11: RO000010 | B11: C0340 | C11: V0013 | D11: T020 | E11: P0149 | F11: 97612 | G11: 3.9 | H11: 1578.98 | I11: 5492 | J11: 8718.58 | K11: 67
A12: RO000011 | B12: C0592 | C12: V1181 | D12: T005 | E12: P0153 | F12: 281167 | G12: 8.4 | H12: 2921.6 | I12: 4427 | J12: 8676.7 | K12: 64
A13: RO000012 | B13: C0699 | C13: V1431 | D13: T029 | E13: P0117 | F13: 285082 | G13: 10.5 | H13: 1998.96 | I13: 456 | J13: 2591.76 | K13: 89
... A10001: RO010000 | B10001: C0875 | C10001: V0329 | D10001: T005 | E10001: P0097 | F10001: 158187 | G10001: 9.7 | H10001: 899.2 | I10001: 7183 | J10001: 10237.1 | K10001: 66

Sheet Dashboard
A1: 📊 لوحة تحليل بيانات مركز الصيانة
A3: 📈 المؤشرات الرئيسية
A4: إجمالي أوامر الإصلاح | B4: =COUNTA(Fact_RepairOrders!A:A)-1 -> 10000
A5: إجمالي العملاء | B5: =COUNTA(Dim_Customers!A:A)-1 -> 1000
A6: إجمالي المركبات | B6: =COUNTA(Dim_Vehicles!A:A)-1 -> 1500
A7: إجمالي الإيرادات | B7: =SUM(Fact_RepairOrders!J:J) -> 81060861
A8: متوسط رضا العملاء (CSI) | B8: =AVERAGE(Fact_RepairOrders!K:K) -> 80.1163
A10: 🏙️ توزيع العملاء حسب المدينة | D10: 👥 توزيع العملاء حسب النوع
A11: المدينة | B11: العدد | D11: النوع | E11: العدد
A12: Alexandria | B12: =COUNTIF(Dim_Customers!C:C,A12) -> 355 | D12: Retail | E12: =COUNTIF(Dim_Customers!D:D,D12) -> 501
A13: Cairo | B13: =COUNTIF(Dim_Customers!C:C,A13) -> 325 | D13: Fleet | E13: =COUNTIF(Dim_Customers!D:D,D13) -> 499
A14: Giza | B14: =COUNTIF(Dim_Customers!C:C,A14) -> 320
A16: 🚗 توزيع المركبات حسب الماركة | D16: 🔧 توزيع الفنيين حسب المستوى
A17: الماركة | B17: العدد | D17: المستوى | E17: العدد
A18: Toyota | B18: =COUNTIF(Dim_Vehicles!C:C,A18) -> 364 | D18: Master | E18: =COUNTIF(Dim_Technicians!C:C,D18) -> 6
A19: Nissan | B19: =COUNTIF(Dim_Vehicles!C:C,A19) -> 399 | D19: Senior | E19: =COUNTIF(Dim_Technicians!C:C,D19) -> 11
A20: Hyundai | B20: =COUNTIF(Dim_Vehicles!C:C,A20) -> 365 | D20: Junior | E20: =COUNTIF(Dim_Technicians!C:C,D20) -> 13
A21: Kia | B21: =COUNTIF(Dim_Vehicles!C:C,A21) -> 372
A23: 💰 ملخص مالي | D23: 🔩 قطع الغيار حسب الفئة
A24: البيان | B24: القيمة | D24: الفئة | E24: العدد
A25: إجمالي الإيرادات | B25: =SUM(Fact_RepairOrders!J:J) -> 81060861 | D25: Engine | E25: =COUNTIF(Dim_Parts!C:C,D25) -> 49
A26: إجمالي تكلفة العمالة | B26: =SUM(Fact_RepairOrders!H:H) -> 16288218 | D26: Brake | E26: =COUNTIF(Dim_Parts!C:C,D26) -> 46
A27: إجمالي تكلفة القطع | B27: =SUM(Fact_RepairOrders!I:I) -> 49825110 | D27: AC | E27: =COUNTIF(Dim_Parts!C:C,D27) -> 52
A28: متوسط الإيراد لكل أمر | B28: =AVERAGE(Fact_RepairOrders!J:J) -> 8106.0861 | D28: Electrical | E28: =COUNTIF(Dim_Parts!C:C,D28) -> 53
A30: 📊 تحليل نقاط القوة والضعف
A32: ✅ نقاط القوة | F32: 🏆 أفضل 5 فنيين (CSI)
A33: 1️⃣ ربحية عالية | B33: هامش ربح 17.1% - لا توجد أوامر خاسرة | F33: الفني | G33: المستوى | H33: CSI
A34: 2️⃣ رضا عملاء جيد | B34: متوسط CSI = 80.1 من 100 | F34: Tech 4 | G34: Senior | H34: 81.32
A35: 3️⃣ توازن جغرافي | B35: توزيع متساوي للإيرادات بين المدن | F35: Tech 18 | G35: Junior | H35: 81.32
A36: 4️⃣ توازن العملاء | B36: Fleet و Retail متقاربين (50/50) | F36: Tech 8 | G36: Junior | H36: 81.07
A37: 5️⃣ إنتاجية عالية | B37: 10,000 أمر إصلاح بـ 30 فني فقط | F37: Tech 12 | G37: Junior | H37: 80.94
F38: Tech 20 | G38: Junior | H38: 80.76
A39: ⚠️ نقاط الضعف | F39: 📉 أسوأ 5 فنيين (CSI)
A40: 1️⃣ رضا عملاء منخفض | B40: 2,438 أمر (24%) بـ CSI أقل من 70 | F40: الفني | G40: المستوى | H40: CSI
A41: 2️⃣ فنيين ضعفاء | B41: Tech 1 (Master) أقل CSI = 78.96 | F41: Tech 1 | G41: Master | H41: 78.96
A42: 3️⃣ تكلفة قطع غيار | B42: 61% من الإيرادات تذهب لقطع الغيار | F42: Tech 7 | G42: Senior | H42: 79.16
A43: 4️⃣ عدم توازن الفنيين | B43: Junior = 13، Senior = 11، Master = 6 | F43: Tech 11 | G43: Junior | H43: 79.41
F44: Tech 23 | G44: Junior | H44: 79.5
F45: Tech 21 | G45: Senior | H45: 79.62
A48: 💡 أفكار وتوصيات لزيادة الربحية
...

Sheet Executive Summary
A1: 📋 الملخص التنفيذي (Executive Summary)
A3: 🎯 الهدف من التقرير
A4: تحليل شامل لأداء مركز الصيانة وتحديد فرص التحسين وزيادة الربحية
A6: 📊 أهم النتائج
A8: المؤشر | B8: النتيجة
A9: إجمالي الإيرادات | B9: 81,060,861 ج.م
A10: صافي الربح | B10: 14,947,533 ج.م (18.4%)
A11: متوسط رضا العملاء | B11: 80.1 من 100
A12: عدد أوامر الإصلاح | B12: 10,000 أمر
A13: متوسط الإيراد/أمر | B13: 8,106 ج.م
A14: إنتاجية الفني | B14: 333 أمر/فني
A16: ✅ أبرز نقاط القوة
A18: 1. هامش ربح صحي (17-18%) - لا توجد أوامر خاسرة
A19: 2. رضا عملاء جيد (80+) مع قاعدة عملاء متوازنة
A20: 3. توزيع جغرافي متوازن للإيرادات
A21: 4. إنتاجية عالية للفنيين (333 أمر/فني)
A22: 5. تنوع في قاعدة العملاء (Fleet 50% - Retail 50%)
A24: ⚠️ أهم التحديات
A26: 1. 24% من الأوامر (2,438) بمستوى رضا أقل من 70
A27: 2. تكلفة قطع الغيار مرتفعة (61% من الإيرادات)
A28: 3. فني Master بأقل CSI - يحتاج تقييم
A29: 4. عدم توازن مستويات الفنيين (Junior أكثر من Master)
A30: 5. غياب البيانات الزمنية للتحليل الموسمي
A32: 💡 أهم التوصيات
A34: التوصية | B34: الأثر المتوقع | C34: الأولوية
A35: تقليل تكلفة قطع الغيار 10% | B35: توفير 5 مليون ج.م | C35: عالية 🔴
A36: رفع أسعار الخدمات 5% | B36: زيادة 4 مليون ج.م | C36: عالية 🔴
A37: معالجة الأوامر منخفضة CSI | B37: تقليل فقدان العملاء | C37: عالية 🔴
A38: تدريب الفنيين الضعفاء | B38: تحسين CSI إلى 85+ | C38: متوسطة 🟡
A39: عقود صيانة للأساطيل | B39: إيرادات مضمونة | C39: متوسطة 🟡
A41: 📈 التأثير المالي المتوقع
A43: البند | B43: التحسين
A44: زيادة الإيرادات | B44: +4-8 مليون ج.م
A45: تقليل التكاليف | B45: 5-8 مليون ج.م
A46: إجمالي التحسين السنوي | B46: 10-15 مليون ج.م
A47: هامش الربح المتوقع | B47: 22-25%
A49: ═══════════════════════════════════════════════════════════════
A50: 🔚 الخلاصة: مركز الصيانة يحقق أداء جيد مع فرص واعدة للتحسين
A51: التركيز على تقليل تكلفة القطع وتحسين رضا العملاء سيحقق أكبر أثر مالي

Sheet Data Dictionary
A1: 📖 قاموس البيانات (Data Dictionary)
A3: ═══════════════════════════════════════════════════════════════
A5: 📋 جدول: Dim_Customers (بيانات العملاء)
A6: العمود | B6: النوع | C6: الوصف | D6: مثال
A7: Customer_ID | B7: Text | C7: معرف العميل الفريد | D7: C0001
A8: Customer_Name | B8: Text | C8: اسم العميل | D8: Customer 1
A9: City | B9: Text | C9: المدينة (Alexandria, Cairo, Giza) | D9: Cairo
A10: Customer_Type | B10: Text | C10: نوع العميل (Fleet, Retail) | D10: Fleet
A12: 📋 جدول: Dim_Vehicles (بيانات المركبات)
A13: العمود | B13: النوع | C13: الوصف | D13: مثال
A14: Vehicle_ID | B14: Text | C14: معرف المركبة الفريد | D14: V0001
A15: Customer_ID | B15: Text | C15: معرف العميل (Foreign Key) | D15: C0608
A16: Brand | B16: Text | C16: ماركة السيارة | D16: Toyota
A17: Model | B17: Text | C17: موديل السيارة | D17: Corolla
A18: Model_Year | B18: Number | C18: سنة الصنع | D18: 2025
A20: 📋 جدول: Dim_Technicians (بيانات الفنيين)
A21: العمود | B21: النوع | C21: الوصف | D21: مثال
A22: Technician_ID | B22: Text | C22: معرف الفني الفريد | D22: T001
A23: Technician_Name | B23: Text | C23: اسم الفني | D23: Tech 1
A24: Level | B24: Text | C24: المستوى (Master, Senior, Junior) | D24: Master
A26: 📋 جدول: Dim_Parts (قطع الغيار)
A27: العمود | B27: النوع | C27: الوصف | D27: مثال
A28: Part_ID | B28: Text | C28: معرف القطعة الفريد | D28: P0001
A29: Part_Name | B29: Text | C29: اسم القطعة | D29: Part 1
A30: Category | B30: Text | C30: الفئة (Engine, Brake, AC, Electrical) | D30: Electrical
A31: Unit_Cost | B31: Number | C31: تكلفة الوحدة بالجنيه | D31: 349
A33: 📋 جدول: Fact_RepairOrders (أوامر الإصلاح)
A34: العمود | B34: النوع | C34: الوصف | D34: مثال
A35: RO_Number | B35: Text | C35: رقم أمر الإصلاح الفريد | D35: RO000001
A36: Customer_ID | B36: Text | C36: معرف العميل (FK) | D36: C0604
A37: Vehicle_ID | B37: Text | C37: معرف المركبة (FK) | D37: V1468
A38: Technician_ID | B38: Text | C38: معرف الفني (FK) | D38: T017
A39: Part_ID | B39: Text | C39: معرف القطعة (FK) | D39: P0189
A40: Mileage | B40: Number | C40: عداد الكيلومترات | D40: 35791
A41: Labor_Hours | B41: Number | C41: ساعات العمل | D41: 6.3
A42: Labor_Cost | B42: Number | C42: تكلفة العمالة بالجنيه | D42: 2489.89
A43: Parts_Cost | B43: Number | C43: تكلفة القطع بالجنيه | D43: 3294
A44: Revenue | B44: Number | C44: إجمالي الإيرادات بالجنيه | D44: 6772.09
A45: CSI_Score | B45: Number | C45: درجة رضا العميل (1-100) | D45: 69
A47: ═══════════════════════════════════════════════════════════════
...

Sheet Skills & Tools
A1: 🛠️ المهارات والأدوات المستخدمة (Skills & Tools)
A3: ═══════════════════════════════════════════════════════════════
A5: 📊 أدوات التحليل
A6: الأداة | B6: الاستخدام
A7: Microsoft Excel | B7: تحليل البيانات وإنشاء التقارير
A8: Power Query | B8: تنظيف وتحويل البيانات
A9: Excel Formulas | B9: الحسابات والتحليلات الديناميكية
A10: Pivot Tables | B10: تلخيص وتحليل البيانات
A12: 📈 المهارات التحليلية
A13: المهارة | B13: التطبيق في المشروع
A14: Descriptive Analytics | B14: حساب المؤشرات الرئيسية KPIs
A15: Data Visualization | B15: إنشاء Dashboard تفاعلي
A16: SWOT Analysis | B16: تحديد نقاط القوة والضعف
A17: Financial Analysis | B17: تحليل الربحية والتكاليف
A18: Performance Benchmarking | B18: مقارنة أداء الفنيين
A20: 💻 المهارات التقنية
A21: المهارة | B21: المستوى
A22: Excel Functions (SUMIF, COUNTIF, AVERAGE) | B22: متقدم ⭐⭐⭐
A23: Data Modeling | B23: متقدم ⭐⭐⭐
A24: Dashboard Design | B24: متقدم ⭐⭐⭐
A25: Data Cleaning | B25: متقدم ⭐⭐⭐
A26: Business Intelligence | B26: متوسط ⭐⭐
A28: 🎯 الصيغ المستخدمة في المشروع
A29: الصيغة | B29: الوظيفة
A30: SUM, SUMIF, SUMIFS | B30: جمع القيم حسب معايير
A31: COUNT, COUNTIF, COUNTIFS | B31: عد السجلات حسب معايير
A32: AVERAGE, AVERAGEIF | B32: حساب المتوسطات
A33: VLOOKUP, INDEX/MATCH | B33: ربط الجداول
A34: IF, IFS, SWITCH | B34: المنطق الشرطي
A35: TEXT, CONCATENATE | B35: تنسيق النصوص
A37: ═══════════════════════════════════════════════════════════════
A39: 🏆 ما يميز هذا المشروع
A40: ✅ تحليل شامل لـ 10,000 سجل
A41: ✅ Dashboard تفاعلي بصيغ ديناميكية
A42: ✅ تحليل SWOT متكامل
A43: ✅ توصيات قابلة للتنفيذ مع أثر مالي
A44: ✅ توثيق كامل للمنهجية
A45: ✅ هيكل بيانات Star Schema
